Workbook
Name INFERIOR: 'COSTO UNITARIO'!$G$17:$G$23
Name SUPERIOR: 'COSTO UNITARIO'!$I$17:$I$20
Name INCAPACIDADES: incap!$B$3:$E$1048576

Sheet SIMULACION 
E1: 30min | F1: 29min
B2: SIMULACIÓN VELOCIDAD
B3: # | C3: # RESES | D3: VELOCIDAD BRUTA (Reses/Hora) | E3: PARADA PROGRAMADA (Hr) | F3: VACIADO LÍNEA (Hr) | G3: DURACIÓN PROCESO DESEADA (Hr) | H3: DURACIÓN EFECTIVA DE PROCESO (Hr) | I3: DURACION EFECTIVA PARA NOQUEAR EL TOTAL | J3: VELOCIDAD NETA (Reses/Hora) | K3: VELOCIDAD NETA NOQUEO/HORA | L3: # RESES/MIN | M3: MIN/RES | P3: NOQUEAR CADA SEG/RES | S3: Información Editable
B4: 1 | C4: 306 | D4: 75 | E4: 0 | F4: 0.49 | G4: =+(C4/D4) -> 4.08 | H4: =+G4-E4 -> 4.08 | I4: =H4-F4 -> 3.59 | J4: =+C4/H4 -> 75 | K4: =+C4/I4 -> 85.236769 | L4: =+K4/60 -> 1.4206128 | M4: =(60/K4)/60/24 -> 0.00048883442 | N4: =+MINUTE(M4) -> 0 | O4: =+SECOND(M4) -> 42 | P4: =+(N4*60)+O4 -> 42
J6: Aca siempre debe dar 75 | K6: A esto se debe avanzar por hora | V6: 60 | W6: 76
C7: HORA DE INICIO | D7: 0.84583333 | V7: 30 | W7: x
C8: ULTIMA PESADA | D8: =+D7+D9 -> 1.0158333 | G8: =C4 -> 306
C9: TIEMPO LABORADO | D9: =+G4/24 -> 0.17 | F9: =G8*4 -> 1224 | G9: =G8*2 -> 612 | P9: 0.33 | R9: 15min | V9: =V7*W6/V6 -> 38
F11: TOLERANCIA | G11: PIELES/ C.G | H11: C.P/SR | P11: 1 | R11: 60 min
C12: 344 | F12: =(F13/F9)*100 -> 0.7 | G12: =(G13/G9)*100 -> 1.5 | H12: =H13/G9*100 -> 1
F13: =F9*0.007 -> 8.568 | G13: =G9*0.015 -> 9.18 | H13: =G9*0.01 -> 6.12 | U13: =13+10+39+5 -> 67
H15: 0.5 | I15: 30 | P15: 0.75 | R15: 45 min
H16: 0.33 | I16: x | J16: =H16*I15/H15 -> 19.8 | P16: 0.67 | R16: 40min
P17: 0.5 | R17: 30 min
I19: si en 60 min | J19: pasan x
C20: TOPE MINIMO | I20: 60 | J20: 76
C21: 344 | I21: 28.5 | J21: x
J22: =I21*J20/I20 -> 36.1
M26: 0.64930556
M27: 0.68402778 | P27: =M27-M26 -> 0.034722222

Sheet RESUMEN DEL DIA 
Y1: En las paradas y al final dejar menos canales
C3: RESUMEN PARCIAL DE SACRIFICIO | K3: =+HOUR(I5) -> 15 | L3: =+MINUTE(I5) -> 5 | O3: HORA | P3: META | R3: OBSERVACIÓN- LIMITANTE | S3: DIFE | Y3: =TODAY() -> 46262 | AA3: SEGUMIENTO A CLIENTES DEL DIA
C4: =NOW() -> 46262.475 | M4: 19 | O4: 0.58333333 | P4: 79 | Q4: 73 | R4: 36 | S4: =P4-Q4 -> 6 | Y4: CLIENTE | Z4: # | AA4: OBSERVACION
C5: # | D5: ITEM | E5: CIFRA/TOTAL | I5: =+I6-E6 -> 46261.629 | L5: =+K3*60+L3 -> 905 | M5: 38 | O5: 0.625 | P5: 79 | Q5: 50 | S5: =P5-Q5 -> 29 | Y5: COLBEEF S.A.S | Z5: 7 | AA5: Van sucias
C6: 1 | D6: Hora de inicio | E6: ='CIERRE DE PROCESO '!D3 -> 0.84583333 | I6: =NOW() -> 46262.475 | J6: =I5*24/60 -> 18504.652 | L6: =+L5/60 -> 15.083333 | M6: 57 | O6: 0.66666667 | P6: 79 | Q6: 29 | S6: =P6-Q6 -> 50 | Y6: CRUZ LEONIDAS | Z6: 21 | AA6: Garantizar lustres y presentacion de canales
C7: 2 | D7: Total de sacrificio | E7: ='CIERRE DE PROCESO '!D2 -> 306 | G7: =I6*24*60 -> 66617963 | I7: hora actual | M7: 76 | O7: 0.70833333 | P7: 79 | Q7: 80 | S7: =P7-Q7 -> -1 | Y7: GOMEZ QUINTERO JUDITH TORCOROMA | Z7: 14 | AA7: Garantizar lustres y presentacion de canales
C8: 3 | D8: Reses sacrificadas | E8: 126 | G8: =G7-785 -> 66617178 | O8: 0.75 | P8: 40 | Q8: 80 | R8: Parada programada 30 min | S8: =P8-Q8 -> -40 | Y8: INVERSIONES ZULUAGA RUEDA S.A.S. | Z8: 14 | AA8: Limpieza y desgrase profundo y retiro de medula al 100%
C9: 4 | D9: Reses faltantes | E9: =E7-E8 -> 180 | O9: 0.79166667 | P9: 79 | Q9: 40 | S9: =P9-Q9 -> 39 | Y9: JAIMES JAIMES LUIS JOSE (FORTUNATO) | Z9: 46 | AA9: Garantizar lustres y presentacion de canales
C10: 5 | D10: Velocidad de línea (Reses/hora) | E10: ='CIERRE DE PROCESO '!D9 -> 255 | G10: =J6/60 -> 308.41086 | O10: 0.83333333 | P10: 79 | Q10: 80 | R10: Parada programada 30 min | S10: =P10-Q10 -> -1 | Y10: PRODUCTOS OFACOL S.A.S. | Z10: 8 | AA10: Van sucias
C11: 6 | D11: Hora estimada de finalización | E11: =O23 -> 0.89791667 | G11: =+E9/60 -> 3 | J11: =+E7-E8 -> 180 | O11: 0.875 | P11: 79 | Q11: 75 | R11: Falla en maquina de pandos 90 min | S11: =P11-Q11 -> 4 | T11: 35 | Y11: SUPERTIENDAS Y DROGUERIA OLIMPICA S.A. | Z11: 95 | AA11: Van sucias
O12: 0.91666667 | P12: 21 | R12: Falla en maquina de pandos 90 min | S12: =P12-Q12 -> 21
O13: 0.95833333 | S13: 36
O14: 1 | S14: 36
O15: 1.0416667 | S15: 36 | AI15: @Gestor LyD @Coordinación Calidad
O16: 1.0833333 | S16: 36
O17: 1.125 | S17: 36
G18: =+G11*60 -> 180 | J18: =+J11/E10 -> 0.70588235 | O18: 1.1666667 | S18: 36
G20: =+G18+G7 -> 66618143 | J20: =+J18+L6 -> 15.789216 | O20: TOTAL | P20: =SUM(P4:P19) -> 614 | Q20: =SUM(Q4:Q19) -> 507
O21: PROYECCION
G22: =G20/60 -> 1110302.4 | J22: =+J20/24 -> 0.65788399 | O22: ULTIMO INSENSIBILIZADO | Q22: ULTIMA CANAL PESADA | AE22: 2311-07182 | AF22: =AF20-3 -> -3 | AG22: =AG20-3 -> -3 | AH22: Este es el peso final descontando las poleas
O23: =Q23-0.01875 -> 0.89791667 | Q23: ='CIERRE DE PROCESO '!D16 -> 0.91666667 | AE23: MERMA | AF23: 2kg | AG23: 2 kg | AH23: Conclusion cada media merma 2kg
O26: TOTAL | P26: =Q20 -> 507
O27: ULTIMO INSENSIBILIZADO
O28: =O23 -> 0.89791667
Z31: RUIZ RODRIGUEZ LUIS HERNAN | AA31: 17
Y35: GRUPO MANZANARES S.A.S. | AA35: Limpias de riñonada y capadura y asegurar choque y PC
Y36: INVERSIONES ZULUAGA RUEDA S.A.S. | AA36: Limpieza y desgrase profundo y retiro de medula al 100%
Y37: CARNES SANTACRUZ S.A.S | AA37: No se les despejan riñones
D38: Ingreso de cuchillas neumaticas | Y38: PETROCASINOS S.A. | AA38: Van sucias
D39: 46062 | Y39: SUPERMERCADOS MAS POR MENOS S.A.S. | AA39: Van sucias y retiro completo de medula
D40: 46087 | Y40: PRODUCTOS OFACOL S.A.S. | AA40: Van sucias
D41: 46118 | Y41: SUPERTIENDAS OLIMPICA S.A.S | AA41: Van sucias
Y42: COLBEEF S.A.S | AA42: Van sucias
Y43: BUFASAN S.A.S. | AA43: Van sucias

Sheet CIERRE DE PROCESO 
I1: =TODAY() -> 46262
C2: Animales beneficiados | D2: ='SIMULACION '!C4 -> 306 | I2: INDICADORES | J2: META | K2: CIERRE DEL DIA | N2: ENTRENAMIENTO | O2: =I1 -> 46262
C3: Hora de inicio | D3: ='SIMULACION '!D7 -> 0.84583333 | I3: INVENTARIO EN CORRALES | K3: 30 | N3: COLABORADOR | O3: PUESTO DE TRABAJO
C4: Hora ultima pesada | D4: 0.91666667 | F4: H.L | I4: TOTAL DE BENEFICIO | K4: =D2 -> 306 | N4: CASTRO CARLOS SAUL | O4: DEGUELLO
C5: Duracion minutos | D5: =(D4-D3)*24*60 -> 102 | F5: =D5/60 -> 1.7 | I5: HORA DE INICIO | K5: =D3 -> 0.84583333 | N5: PINTON MARLON | O5: RAYADO Y CORTE DE MANOS
C6: paradas presentadas | D6: =F10 -> 0 | I6: HORA FIN | K6: =D4 -> 0.91666667 | N6: JUAN GABRIEL HERNÁNDEZ | O6: AUX. DESUELLO MECANICO
C7: Comida o descanso de personal | D7: 30 | I7: TIEMPO IMPRODUCTIVO (min) | K7: =F10 -> 0 | N7: AYALA CRISTIAN | O7: DESUELLO PRIMERA PIERNA
C8: Productividad | D8: =D2/((D5-D7)/60) -> 255 | E8: 75 | I8: PARADAS PROGRAMADAS (min) | K8: =D7 -> 30 | N8: GUERRERO MIGUEL ANGEL | O8: CORTE DE ESTERNON
C9: Neta | D9: =D2/((D5-(D6+D7))/60) -> 255 | E9: 75 | I9: VELOCIDAD LÍNEA DE BENEFICIO | K9: =K13 -> 255
C10: Bruta | D10: =D2/F5 -> 180 | E10: 75 | F10: =SUM(F6:F9) -> 0 | I10: HORAS LABORADAS | K10: =F5 -> 1.7
I11: TARDANZA DE INICIO | K11: 0
I12: PRODUCTIVIDAD | J12: 55 | K12: =D8 -> 255
I13: VELOCIDAD NETA | J13: 74.55 | K13: =D9 -> 255
C14: TIEMPO DE VACIADO DE LINEA | D14: 0.01875 | I14: VELOCIDAD BRUTA | J14: 55 | K14: =D10 -> 180
C15: ULTIMO INSENSIBILIZADO | D15: =(D4-D14) -> 0.89791667 | I15: TOLERANCIA CERO | J15: 0.01 | K15: 0.0032
C16: ULTIMA CANAL PESADA | D16: =D4 -> 0.91666667 | I16: PIELES | J16: 0.031 | K16: ='CIERRE DE PIELES '!D14/D2 -> 0.081699346
D17: =D16-0.01875 -> 0.89791667 | I17: CORTE EN PIERNA | J17: 0.01 | K17: =IFERROR(VLOOKUP($I$1,'LIBERACION DE CANALES'!B:K,9,FALSE),"DOM") -> DOM
I18: SOBREBARRIGAS ROTAS | J18: 0.01 | K18: =IFERROR(VLOOKUP($I$1,'LIBERACION DE CANALES'!B:K,10,FALSE),"DOM") -> DOM
I19: COBERTURA GRASA | J19: 0.015 | K19: =IFERROR(VLOOKUP($I$1,'LIBERACION DE CANALES'!B:K,7,FALSE),"DOM") -> DOM
I20: DIAS SIN ACCIDENTES | J20: 60 | K20: 0
AU64: DIA | AV64: VELOCIDAD BRUTA | AW64: NOVEDAD
AU65: 13 DE JULIO | AV65: 44 | AW65: Se realiza caractirizacion en la PTAR con velocidad permitida de 44
AU66: 15 DE JULIO | AV66: 53 | AW66: Se presenta ruptura de la tuberia de la bañadera de corrales, lo que nos genera 30 min de tiempos improductivos
AU67: 18 DE JULIO | AV67: 53 | AW67: Se presenta falla mecanica en la trasferencia numero 1, y no se logra solucionar lo que nos implico terminar a un ritmo menor con la trasferencia
AU68: 22 DE JULIO | AV68: 52 | AW68: Se presentan parada de 30 min por altas temperaturas en el cuarto de pre refrigeracion oreo
AU69: 25 DE JULIO | AV69: 53 | AW69: Se presenta parada de 30min de tiempo improductivo por motivo de que no se contaba con ganchos para colgar viscera roja
I88: CIERRE DE OCTUBRE 2025
I89: INDICADORES | J89: META | K89: CIERRE DEL MES
I90: O.E.E. | J90: 0.95 | K90: 0.923
I91: PRODUCTIVIDAD | J91: 55 | K91: 57
I92: VELOCIDAD NETA | J92: 75 | K92: 75
I93: VELOCIDAD BRUTA | J93: 55 | K93: 54
I94: TOLERANCIA CERO | J94: 0.01 | K94: 0.006
I95: PIELES | J95: 0.03 | K95: 0.0223
I96: CORTE EN PIERNA | J96: 0.01 | K96: 0.004
I97: SOBREBARRIGAS ROTAS | J97: 0.01 | K97: 0.005
I98: HEMATOMAS | J98: 0.005 | K98: 0.001
I99: COBERTURA GRASA | J99: 0.015 | K99: 0.004
I100: DIAS SIN ACCIDENTES | J100: 0 | K100: 68 DIAS SIN A.T.

Sheet CIERRE DE PROCESO
C1: =UPPER(TEXT(B3,"MMMM")) -> AGOSTO
B2: CIERRE DE PROCESO LÍNEA DE BENEFICIO | E2: FALLOS EN MAQUINARIA | G2: OBSERVACIONES DE PROCESO | L2: =IFERROR(__xludf.DUMMYFUNCTION("IMPORTRANGE(""https://docs.google.com/spreadsheets/d/1OjTekbeLGM33cmRz9M_4nXVIyMrUrINjwBqTFNIG2fQ/edit?gid=440714860#gid=440714860"",""RESUMEN!H3:M12"")"),"OPERATIVIDAD DE LINEA") -> OPERATIVIDAD DE LINEA | M2: =IFERROR(__xludf.DUMMYFUNCTION("""COMPUTED_VALUE"""),"REAL") -> REAL | N2: =IFERROR(__xludf.DUMMYFUNCTION("""COMPUTED_VALUE"""),"%") -> % | O2: =IFERROR(__xludf.DUMMYFUNCTION("""COMPUTED_VALUE"""),46261.0) -> 46261 | Q2: =IFERROR(__xludf.DUMMYFUNCTION("""COMPUTED_VALUE"""),"DIF") -> DIF | S2: EJECUCIÓN PTTO BENEFICIO - 2026
B3: 46261 | E3: 1- No se cuenta con contingencias habilitadas, desolladora, sierra canal y box de noqueo . | G3: =VLOOKUP($B$3,'BASE DE DATOS CIERRE'!A:V,22,0) -> 1. Se registra parada por tanque cañón ruminal tapado (20) | L3: =IFERROR(__xludf.DUMMYFUNCTION("""COMPUTED_VALUE"""),"LIDER/APOYO") -> LIDER/APOYO | M3: =IFERROR(__xludf.DUMMYFUNCTION("""COMPUTED_VALUE"""),1.0) -> 1 | N3: =IFERROR(__xludf.DUMMYFUNCTION("""COMPUTED_VALUE"""),0.016666666666666666) -> 0.016666667 | O3: =IFERROR(__xludf.DUMMYFUNCTION("""COMPUTED_VALUE"""),0.0) -> 0 | P3: =IFERROR(__xludf.DUMMYFUNCTION("""COMPUTED_VALUE"""),0.0) -> 0 | Q3: =IFERROR(__xludf.DUMMYFUNCTION("""COMPUTED_VALUE"""),-0.016666666666666666) -> -0.016666667 | S3: # | T3: MES | U3: PPTO MES | V3: RESES BENEFICIADAS | W3: % CUMPL.
B4: INDICADORES | L4: =IFERROR(__xludf.DUMMYFUNCTION("""COMPUTED_VALUE"""),"OPERACION") -> OPERACION | M4: =IFERROR(__xludf.DUMMYFUNCTION("""COMPUTED_VALUE"""),45.0) -> 45 | N4: =IFERROR(__xludf.DUMMYFUNCTION("""COMPUTED_VALUE"""),0.75) -> 0.75 | O4: =IFERROR(__xludf.DUMMYFUNCTION("""COMPUTED_VALUE"""),48.0) -> 48 | P4: =IFERROR(__xludf.DUMMYFUNCTION("""COMPUTED_VALUE"""),0.8) -> 0.8 | Q4: =IFERROR(__xludf.DUMMYFUNCTION("""COMPUTED_VALUE"""),0.050000000000000044) -> 0.05 | S4: 1 | T4: ENERO | U4: 12366 | V4: 11514 | W4: =IF(V4="","",V4/U4) -> 0.93110141
B5: TOTAL DE BENEFICIO | C5: =VLOOKUP($B$3,'BASE DE DATOS CIERRE'!A:AA,3,0) -> 440 | L5: =IFERROR(__xludf.DUMMYFUNCTION("""COMPUTED_VALUE"""),"VACACIONES") -> VACACIONES | M5: =IFERROR(__xludf.DUMMYFUNCTION("""COMPUTED_VALUE"""),3.0) -> 3 | N5: =IFERROR(__xludf.DUMMYFUNCTION("""COMPUTED_VALUE"""),0.05) -> 0.05 | O5: =IFERROR(__xludf.DUMMYFUNCTION("""COMPUTED_VALUE"""),1.0) -> 1 | P5: =IFERROR(__xludf.DUMMYFUNCTION("""COMPUTED_VALUE"""),0.016666666666666666) -> 0.016666667 | Q5: =IFERROR(__xludf.DUMMYFUNCTION("""COMPUTED_VALUE"""),0.03333333333333334) -> 0.033333333 | S5: 2 | T5: FEBRERO | U5: 11925 | V5: 10786 | W5: =IF(V5="","",V5/U5) -> 0.90448637
B6: HORA DE INICIO | C6: =VLOOKUP($B$3,'BASE DE DATOS CIERRE'!A:AA,4,0) -> 0.63194444 | L6: =IFERROR(__xludf.DUMMYFUNCTION("""COMPUTED_VALUE"""),"INC, DF, SUS, PER, PAT") -> INC, DF, SUS, PER, PAT | M6: =IFERROR(__xludf.DUMMYFUNCTION("""COMPUTED_VALUE"""),4.0) -> 4 | N6: =IFERROR(__xludf.DUMMYFUNCTION("""COMPUTED_VALUE"""),0.06666666666666667) -> 0.066666667 | O6: =IFERROR(__xludf.DUMMYFUNCTION("""COMPUTED_VALUE"""),6.0) -> 6 | P6: =IFERROR(__xludf.DUMMYFUNCTION("""COMPUTED_VALUE"""),0.1) -> 0.1 | Q6: =IFERROR(__xludf.DUMMYFUNCTION("""COMPUTED_VALUE"""),-0.03333333333333334) -> -0.033333333 | S6: 3 | T6: MARZO | U6: 12157 | V6: 12094 | W6: =IF(V6="","",V6/U6) -> 0.9948178
B7: HORA FIN | C7: =VLOOKUP($B$3,'BASE DE DATOS CIERRE'!A:AA,5,0) -> 0.91180556 | L7: =IFERROR(__xludf.DUMMYFUNCTION("""COMPUTED_VALUE"""),"POR CONTRATAR") -> POR CONTRATAR | M7: =IFERROR(__xludf.DUMMYFUNCTION("""COMPUTED_VALUE"""),0.0) -> 0 | N7: =IFERROR(__xludf.DUMMYFUNCTION("""COMPUTED_VALUE"""),0.0) -> 0 | O7: =IFERROR(__xludf.DUMMYFUNCTION("""COMPUTED_VALUE"""),0.0) -> 0 | P7: =IFERROR(__xludf.DUMMYFUNCTION("""COMPUTED_VALUE"""),0.0) -> 0 | Q7: =IFERROR(__xludf.DUMMYFUNCTION("""COMPUTED_VALUE"""),0.0) -> 0 | S7: 4 | T7: ABRIL | U7: 11728 | V7: =SUMIF('BASE DE DATOS CIERRE'!AC:AC,T7,'BASE DE DATOS CIERRE'!C:C) -> 10983 | W7: =IF(V7="","",V7/U7) -> 0.93647681
B8: INDICADOR O.E.E (Mes) | C8: =VLOOKUP(C1,'CONSOLIDADO OEE'!B:O,13,0) -> 0.88163128 | L8: =IFERROR(__xludf.DUMMYFUNCTION("""COMPUTED_VALUE"""),"REUBICADO") -> REUBICADO | M8: =IFERROR(__xludf.DUMMYFUNCTION("""COMPUTED_VALUE"""),1.0) -> 1 | N8: =IFERROR(__xludf.DUMMYFUNCTION("""COMPUTED_VALUE"""),0.016666666666666666) -> 0.016666667 | O8: =IFERROR(__xludf.DUMMYFUNCTION("""COMPUTED_VALUE"""),2.0) -> 2 | P8: =IFERROR(__xludf.DUMMYFUNCTION("""COMPUTED_VALUE"""),0.03333333333333333) -> 0.033333333 | Q8: =IFERROR(__xludf.DUMMYFUNCTION("""COMPUTED_VALUE"""),0.016666666666666666) -> 0.016666667 | S8: 5 | T8: MAYO | U8: 12554 | V8: =SUMIF('BASE DE DATOS CIERRE'!AC:AC,T8,'BASE DE DATOS CIERRE'!C:C) -> 12904 | W8: =IF(V8="","",V8/U8) -> 1.0278796
B9: INDICADOR O.E.E (Dia) | C9: =VLOOKUP($B$3,'BASE DE DATOS CIERRE'!A:AA,2,0) -> 0.91233147 | L9: =IFERROR(__xludf.DUMMYFUNCTION("""COMPUTED_VALUE"""),"ENTRENAMIENTO") -> ENTRENAMIENTO | M9: =IFERROR(__xludf.DUMMYFUNCTION("""COMPUTED_VALUE"""),3.0) -> 3 | N9: =IFERROR(__xludf.DUMMYFUNCTION("""COMPUTED_VALUE"""),0.05) -> 0.05 | O9: =IFERROR(__xludf.DUMMYFUNCTION("""COMPUTED_VALUE"""),3.0) -> 3 | P9: =IFERROR(__xludf.DUMMYFUNCTION("""COMPUTED_VALUE"""),0.05) -> 0.05 | Q9: =IFERROR(__xludf.DUMMYFUNCTION("""COMPUTED_VALUE"""),0.0) -> 0 | S9: 6 | T9: JUNIO | U9: 12635 | V9: =SUMIF('BASE DE DATOS CIERRE'!AC:AC,T9,'BASE DE DATOS CIERRE'!C:C) -> 12920 | W9: =IF(V9="","",V9/U9) -> 1.0225564
B10: VELOCIDAD LÍNEA DE BENEFICIO | C10: =VLOOKUP($B$3,'BASE DE DATOS CIERRE'!A:AA,9,0) -> 74.787535 | L10: =IFERROR(__xludf.DUMMYFUNCTION("""COMPUTED_VALUE"""),"INCAPACIDAD LARGAS") -> INCAPACIDAD LARGAS | M10: =IFERROR(__xludf.DUMMYFUNCTION("""COMPUTED_VALUE"""),0.0) -> 0 | N10: =IFERROR(__xludf.DUMMYFUNCTION("""COMPUTED_VALUE"""),0.0) -> 0 | O10: =IFERROR(__xludf.DUMMYFUNCTION("""COMPUTED_VALUE"""),1.0) -> 1 | P10: =IFERROR(__xludf.DUMMYFUNCTION("""COMPUTED_VALUE"""),0.0) -> 0 | S10: 7 | T10: JULIO | U10: 12797 | V10: =SUMIF('BASE DE DATOS CIERRE'!AC:AC,T10,'BASE DE DATOS CIERRE'!C:C) -> 13022 | W10: =IF(V10="","",V10/U10) -> 1.0175822
B11: HORAS LABORADAS | C11: =VLOOKUP($B$3,'BASE DE DATOS CIERRE'!A:AA,10,0) -> 6.7166667 | M11: =IFERROR(__xludf.DUMMYFUNCTION("""COMPUTED_VALUE"""),60.0) -> 60 | O11: =IFERROR(__xludf.DUMMYFUNCTION("""COMPUTED_VALUE"""),60.0) -> 60 | S11: 8 | T11: AGOSTO | U11: 12843 | V11: =SUMIF('BASE DE DATOS CIERRE'!AC:AC,T11,'BASE DE DATOS CIERRE'!C:C) -> 10982 | W11: =IF(V11="","",V11/U11) -> 0.85509616
B12: TARDANZA DE INICIO | C12: =VLOOKUP($B$3,'BASE DE DATOS CIERRE'!A:AA,11,0) -> 0 | E12: OPERATIVIDAD LINEA DE BENEFICIO | S12: 9 | T12: SEPTIEMBRE | U12: 12905 | V12: =SUMIF('BASE DE DATOS CIERRE'!AC:AC,T12,'BASE DE DATOS CIERRE'!C:C) -> 0 | W12: =IF(V12="","",V12/U12) -> 0
B13: INDICADORES | E13: ITEM | F13: CRITERIO | G13: # PERSONAL | H13: % DE PART. | I13: COLABORADOR | S13: 10 | T13: OCTUBRE | U13: 13939 | V13: =SUMIF('BASE DE DATOS CIERRE'!AC:AC,T13,'BASE DE DATOS CIERRE'!C:C) -> 0 | W13: =IF(V13="","",V13/U13) -> 0
B14: PRODUCTIVIDAD | C14: =VLOOKUP($B$3,'BASE DE DATOS CIERRE'!A:AA,12,0) -> 70.77748 | E14: 1 | F14: =IFERROR(__xludf.DUMMYFUNCTION("IMPORTRANGE(""https://docs.google.com/spreadsheets/d/1OjTekbeLGM33cmRz9M_4nXVIyMrUrINjwBqTFNIG2fQ/edit?gid=440714860#gid=440714860"",""RESUMEN!C26:F34"")"),"LABORANDO") -> LABORANDO | G14: =IFERROR(__xludf.DUMMYFUNCTION("""COMPUTED_VALUE"""),51.0) -> 51 | H14: =IFERROR(__xludf.DUMMYFUNCTION("""COMPUTED_VALUE"""),0.85) -> 0.85 | I14: =IFERROR(__xludf.DUMMYFUNCTION("""COMPUTED_VALUE"""),"") | S14: 11 | T14: NOVIEMBRE | U14: 13909 | V14: =SUMIF('BASE DE DATOS CIERRE'!AC:AC,T14,'BASE DE DATOS CIERRE'!C:C) -> 0 | W14: =IF(V14="","",V14/U14) -> 0
B15: VELOCIDAD NETA | C15: =VLOOKUP($B$3,'BASE DE DATOS CIERRE'!A:AA,13,0) -> 74.787535 | E15: =IF(F15="","",E14+1) -> 2 | F15: =IFERROR(__xludf.DUMMYFUNCTION("""COMPUTED_VALUE"""),"VACACIONES") -> VACACIONES | G15: =IFERROR(__xludf.DUMMYFUNCTION("""COMPUTED_VALUE"""),1.0) -> 1 | H15: =IFERROR(__xludf.DUMMYFUNCTION("""COMPUTED_VALUE"""),0.016666666666666666) -> 0.016666667 | I15: =IFERROR(__xludf.DUMMYFUNCTION("""COMPUTED_VALUE"""),"QUINTERO GERSON") -> QUINTERO GERSON | S15: 12 | T15: DICIEMBRE | U15: 14752 | V15: =SUMIF('BASE DE DATOS CIERRE'!AC:AC,T15,'BASE DE DATOS CIERRE'!C:C) -> 0 | W15: =IF(V15="","",V15/U15) -> 0
B16: VELOCIDAD BRUTA | C16: =VLOOKUP($B$3,'BASE DE DATOS CIERRE'!A:AA,14,0) -> 65.508685 | E16: =IF(F16="","",E15+1) -> 3 | F16: =IFERROR(__xludf.DUMMYFUNCTION("""COMPUTED_VALUE"""),"INCAPACIDAD") -> INCAPACIDAD | G16: =IFERROR(__xludf.DUMMYFUNCTION("""COMPUTED_VALUE"""),3.0) -> 3 | H16: =IFERROR(__xludf.DUMMYFUNCTION("""COMPUTED_VALUE"""),0.05) -> 0.05 | I16: =IFERROR(__xludf.DUMMYFUNCTION("""COMPUTED_VALUE"""),"MANTILLA LUIS/ PADILLA MILEXANDE/ PAJARO YAIR") -> MANTILLA LUIS/ PADILLA MILEXANDE/ PAJARO YAIR | S16: TOTAL | U16: =SUM(U4:U15) -> 154510 | V16: =SUM(V4:V15) -> 95205 | W16: =V16/U16 -> 0.61617371
B17: TOLERANCIA CERO | C17: =VLOOKUP($B$3,'BASE DE DATOS CIERRE'!A:AA,15,0) -> 0.0068 | E17: =IF(F17="","",E16+1) -> 4 | F17: =IFERROR(__xludf.DUMMYFUNCTION("""COMPUTED_VALUE"""),"AMORTIZAR EXTRAS") -> AMORTIZAR EXTRAS | G17: =IFERROR(__xludf.DUMMYFUNCTION("""COMPUTED_VALUE"""),1.0) -> 1 | H17: =IFERROR(__xludf.DUMMYFUNCTION("""COMPUTED_VALUE"""),0.016666666666666666) -> 0.016666667 | I17: =IFERROR(__xludf.DUMMYFUNCTION("""COMPUTED_VALUE"""),"JOSE BAUTISTA") -> JOSE BAUTISTA
B18: PIELES | C18: =VLOOKUP($B$3,'BASE DE DATOS CIERRE'!A:AA,16,0) -> 0.056818182 | E18: =IF(F18="","",E17+1) -> 5 | F18: =IFERROR(__xludf.DUMMYFUNCTION("""COMPUTED_VALUE"""),"REUBICADO") -> REUBICADO | G18: =IFERROR(__xludf.DUMMYFUNCTION("""COMPUTED_VALUE"""),2.0) -> 2 | H18: =IFERROR(__xludf.DUMMYFUNCTION("""COMPUTED_VALUE"""),0.03333333333333333) -> 0.033333333 | I18: =IFERROR(__xludf.DUMMYFUNCTION("""COMPUTED_VALUE"""),"CANCINO JAVIER/ MORALES EFRAIN") -> CANCINO JAVIER/ MORALES EFRAIN
B19: CORTE EN PIERNA | C19: =VLOOKUP($B$3,'BASE DE DATOS CIERRE'!A:AA,17,0) -> 0.008 | E19: =IF(F19="","",E18+1) -> 6 | F19: =IFERROR(__xludf.DUMMYFUNCTION("""COMPUTED_VALUE"""),"RENUNCIA") -> RENUNCIA | G19: =IFERROR(__xludf.DUMMYFUNCTION("""COMPUTED_VALUE"""),1.0) -> 1 | H19: =IFERROR(__xludf.DUMMYFUNCTION("""COMPUTED_VALUE"""),0.016666666666666666) -> 0.016666667 | I19: =IFERROR(__xludf.DUMMYFUNCTION("""COMPUTED_VALUE"""),"SUAREZ ANDREY") -> SUAREZ ANDREY
B20: SOBREBARRIGAS ROTAS | C20: =VLOOKUP($B$3,'BASE DE DATOS CIERRE'!A:AA,18,0) -> 0.01 | E20: =IF(F20="","",E19+1) -> 7 | F20: =IFERROR(__xludf.DUMMYFUNCTION("""COMPUTED_VALUE"""),"DIA DE CERO A.T.") -> DIA DE CERO A.T. | G20: =IFERROR(__xludf.DUMMYFUNCTION("""COMPUTED_VALUE"""),1.0) -> 1 | H20: =IFERROR(__xludf.DUMMYFUNCTION("""COMPUTED_VALUE"""),0.016666666666666666) -> 0.016666667 | I20: =IFERROR(__xludf.DUMMYFUNCTION("""COMPUTED_VALUE"""),"BARAJAS EULISIS") -> BARAJAS EULISIS
B21: COBERTURA GRASA | C21: =VLOOKUP($B$3,'BASE DE DATOS CIERRE'!A:AA,19,0) -> 0.0148 | E21: =IF(F21="","",E20+1)
B22: PARADAS PROGRAMADAS (min) | C22: =VLOOKUP($B$3,'BASE DE DATOS CIERRE'!A:AA,8,0) -> 30 | E22: =IF(F22="","",E21+1)
B23: TIEMPOS IMPRODUCTIVOS (min) | C23: =VLOOKUP($B$3,'BASE DE DATOS CIERRE'!A:AA,7,0) -> 20 | E23: TOTAL | G23: =SUM(G14:G22) -> 60 | H23: =SUM(H14:H22) -> 1 | I23: TOTAL AUSENTISMO | J23: =H23-H14 -> 0.15
B25: CIERRE DE PROCESO PRODUCTOS CARNICOS COM | E25: OPERATIVIDAD DE PRODUCTOS CARNICOS COMESTIBLES | L25: =IFERROR(__xludf.DUMMYFUNCTION("IMPORTRANGE(""https://docs.google.com/spreadsheets/d/1CNeKSHTeNNJnfn5EymHwGg5Mkuk6EcepW7_9QkJxalc/edit#gid=206977277"",""RESUMEN!H3:M11"")"),"OPERATIVIDAD DE PCCOM") -> OPERATIVIDAD DE PCCOM | M25: =IFERROR(__xludf.DUMMYFUNCTION("""COMPUTED_VALUE"""),"REAL") -> REAL | N25: =IFERROR(__xludf.DUMMYFUNCTION("""COMPUTED_VALUE"""),"%") -> % | O25: =IFERROR(__xludf.DUMMYFUNCTION("""COMPUTED_VALUE"""),46261.0) -> 46261 | Q25: =IFERROR(__xludf.DUMMYFUNCTION("""COMPUTED_VALUE"""),"DIF") -> DIF
B26: =IFERROR(__xludf.DUMMYFUNCTION("TRANSPOSE(IMPORTRANGE(""https://docs.google.com/spreadsheets/d/1D9Gaq0vid86JLkis77sokTcYmnzylSayfOL-qSUIuis/edit#gid=1366970263"",""CONSOLIDADO DE CIERRE!A1:L1""))"),"FECHA ") -> FECHA | C26: =$B$3 -> 46261 | E26: ITEM | F26: CRITERIO | G26: # PERSONAL | H26: % DE PART. | I26: COLABORADOR | L26: =IFERROR(__xludf.DUMMYFUNCTION("""COMPUTED_VALUE"""),"LIDER/APOYO") -> LIDER/APOYO | M26: =IFERROR(__xludf.DUMMYFUNCTION("""COMPUTED_VALUE"""),2.0) -> 2 | N26: =IFERROR(__xludf.DUMMYFUNCTION("""COMPUTED_VALUE"""),0.0392156862745098) -> 0.039215686 | O26: =IFERROR(__xludf.DUMMYFUNCTION("""COMPUTED_VALUE"""),2.0) -> 2 | P26: =IFERROR(__xludf.DUMMYFUNCTION("""COMPUTED_VALUE"""),0.038461538461538464) -> 0.038461538 | Q26: =IFERROR(__xludf.DUMMYFUNCTION("""COMPUTED_VALUE"""),-7.541478129713397E-4) -> -0.00075414781
B27: =IFERROR(__xludf.DUMMYFUNCTION("""COMPUTED_VALUE"""),"TOTAL DE BENEFICO") -> TOTAL DE BENEFICO | C27: =VLOOKUP($B$3,'CONSOLIDADO DE CIERRE'!$A:$L,2,0) -> 440 | E27: 1 | F27: =IFERROR(__xludf.DUMMYFUNCTION("IMPORTRANGE(""https://docs.google.com/spreadsheets/d/1CNeKSHTeNNJnfn5EymHwGg5Mkuk6EcepW7_9QkJxalc/edit#gid=206977277"",""RESUMEN!C26:F35"")"),"LABORANDO") -> LABORANDO | G27: =IFERROR(__xludf.DUMMYFUNCTION("""COMPUTED_VALUE"""),48.0) -> 48 | H27: =IFERROR(__xludf.DUMMYFUNCTION("""COMPUTED_VALUE"""),0.9230769230769231) -> 0.92307692 | I27: =IFERROR(__xludf.DUMMYFUNCTION("""COMPUTED_VALUE"""),"") | L27: =IFERROR(__xludf.DUMMYFUNCTION("""COMPUTED_VALUE"""),"OPERACION") -> OPERACION | M27: =IFERROR(__xludf.DUMMYFUNCTION("""COMPUTED_VALUE"""),41.0) -> 41 | N27: =IFERROR(__xludf.DUMMYFUNCTION("""COMPUTED_VALUE"""),0.803921568627451) -> 0.80392157 | O27: =IFERROR(__xludf.DUMMYFUNCTION("""COMPUTED_VALUE"""),46.0) -> 46 | P27: =IFERROR(__xludf.DUMMYFUNCTION("""COMPUTED_VALUE"""),0.8846153846153846) -> 0.88461538 | Q27: =IFERROR(__xludf.DUMMYFUNCTION("""COMPUTED_VALUE"""),0.08069381598793357) -> 0.080693816
B28: =IFERROR(__xludf.DUMMYFUNCTION("""COMPUTED_VALUE"""),"HORA INICIO CABEZAS") -> HORA INICIO CABEZAS | C28: =VLOOKUP($B$3,'CONSOLIDADO DE CIERRE'!$A:$L,3,0) -> 0.63194444 | E28: =IF(F28="","",E27+1) -> 2 | F28: =IFERROR(__xludf.DUMMYFUNCTION("""COMPUTED_VALUE"""),"INCAPACIDAD") -> INCAPACIDAD | G28: =IFERROR(__xludf.DUMMYFUNCTION("""COMPUTED_VALUE"""),1.0) -> 1 | H28: =IFERROR(__xludf.DUMMYFUNCTION("""COMPUTED_VALUE"""),0.019230769230769232) -> 0.019230769 | I28: =IFERROR(__xludf.DUMMYFUNCTION("""COMPUTED_VALUE"""),"AGUDELO DANIEL") -> AGUDELO DANIEL | L28: =IFERROR(__xludf.DUMMYFUNCTION("""COMPUTED_VALUE"""),"VACACIONES") -> VACACIONES | M28: =IFERROR(__xludf.DUMMYFUNCTION("""COMPUTED_VALUE"""),3.0) -> 3 | N28: =IFERROR(__xludf.DUMMYFUNCTION("""COMPUTED_VALUE"""),0.058823529411764705) -> 0.058823529 | O28: =IFERROR(__xludf.DUMMYFUNCTION("""COMPUTED_VALUE"""),0.0) -> 0 | P28: =IFERROR(__xludf.DUMMYFUNCTION("""COMPUTED_VALUE"""),0.0) -> 0 | Q28: =IFERROR(__xludf.DUMMYFUNCTION("""COMPUTED_VALUE"""),0.058823529411764705) -> 0.058823529
B29: =IFERROR(__xludf.DUMMYFUNCTION("""COMPUTED_VALUE"""),"HORA ULTIMA VISCERA AMARRADA") -> HORA ULTIMA VISCERA AMARRADA | C29: =VLOOKUP($B$3,'CONSOLIDADO DE CIERRE'!$A:$L,4,0) -> 0.93958333 | E29: =IF(F29="","",E28+1) -> 3 | F29: =IFERROR(__xludf.DUMMYFUNCTION("""COMPUTED_VALUE"""),"REUBICADO") -> REUBICADO | G29: =IFERROR(__xludf.DUMMYFUNCTION("""COMPUTED_VALUE"""),1.0) -> 1 | H29: =IFERROR(__xludf.DUMMYFUNCTION("""COMPUTED_VALUE"""),0.019230769230769232) -> 0.019230769 | I29: =IFERROR(__xludf.DUMMYFUNCTION("""COMPUTED_VALUE"""),"RENGIFO OSCAR") -> RENGIFO OSCAR | L29: =IFERROR(__xludf.DUMMYFUNCTION("""COMPUTED_VALUE"""),"INC, DF, SUS, PER, PAT") -> INC, DF, SUS, PER, PAT | M29: =IFERROR(__xludf.DUMMYFUNCTION("""COMPUTED_VALUE"""),4.0) -> 4 | N29: =IFERROR(__xludf.DUMMYFUNCTION("""COMPUTED_VALUE"""),0.0784313725490196) -> 0.078431373 | O29: =IFERROR(__xludf.DUMMYFUNCTION("""COMPUTED_VALUE"""),1.0) -> 1 | P29: =IFERROR(__xludf.DUMMYFUNCTION("""COMPUTED_VALUE"""),0.019230769230769232) -> 0.019230769 | Q29: =IFERROR(__xludf.DUMMYFUNCTION("""COMPUTED_VALUE"""),0.059200603318250375) -> 0.059200603
B30: =IFERROR(__xludf.DUMMYFUNCTION("""COMPUTED_VALUE"""),"TOTAL PAROS ") -> TOTAL PAROS | C30: =VLOOKUP($B$3,'CONSOLIDADO DE CIERRE'!$A:$L,5,0) -> 0.83333333 | E30: =IF(F30="","",E29+1) -> 4 | F30: =IFERROR(__xludf.DUMMYFUNCTION("""COMPUTED_VALUE"""),"PDTE POR CONTRATAR") -> PDTE POR CONTRATAR | G30: =IFERROR(__xludf.DUMMYFUNCTION("""COMPUTED_VALUE"""),2.0) -> 2 | H30: =IFERROR(__xludf.DUMMYFUNCTION("""COMPUTED_VALUE"""),0.038461538461538464) -> 0.038461538 | L30: =IFERROR(__xludf.DUMMYFUNCTION("""COMPUTED_VALUE"""),"POR CONTRATAR") -> POR CONTRATAR | M30: =IFERROR(__xludf.DUMMYFUNCTION("""COMPUTED_VALUE"""),0.0) -> 0 | N30: =IFERROR(__xludf.DUMMYFUNCTION("""COMPUTED_VALUE"""),0.0) -> 0 | O30: =IFERROR(__xludf.DUMMYFUNCTION("""COMPUTED_VALUE"""),2.0) -> 2 | P30: =IFERROR(__xludf.DUMMYFUNCTION("""COMPUTED_VALUE"""),0.038461538461538464) -> 0.038461538 | Q30: =IFERROR(__xludf.DUMMYFUNCTION("""COMPUTED_VALUE"""),0.038461538461538464) -> 0.038461538
B31: =IFERROR(__xludf.DUMMYFUNCTION("""COMPUTED_VALUE"""),"DURACIÓN PROCESO (Hrs)") -> DURACIÓN PROCESO (Hrs) | C31: =VLOOKUP($B$3,'CONSOLIDADO DE CIERRE'!$A:$L,6,0) -> 7.3833333 | E31: =IF(F31="","",E30+1) | L31: =IFERROR(__xludf.DUMMYFUNCTION("""COMPUTED_VALUE"""),"REUBICADO") -> REUBICADO | M31: =IFERROR(__xludf.DUMMYFUNCTION("""COMPUTED_VALUE"""),1.0) -> 1 | N31: =IFERROR(__xludf.DUMMYFUNCTION("""COMPUTED_VALUE"""),0.0196078431372549) -> 0.019607843 | O31: =IFERROR(__xludf.DUMMYFUNCTION("""COMPUTED_VALUE"""),1.0) -> 1 | P31: =IFERROR(__xludf.DUMMYFUNCTION("""COMPUTED_VALUE"""),0.019230769230769232) -> 0.019230769 | Q31: =IFERROR(__xludf.DUMMYFUNCTION("""COMPUTED_VALUE"""),-3.7707390648566985E-4) -> -0.00037707391
B32: =IFERROR(__xludf.DUMMYFUNCTION("""COMPUTED_VALUE"""),"RENDIMIENTO BRUTO (visceras/hora)") -> RENDIMIENTO BRUTO (visceras/hora) | C32: =VLOOKUP($B$3,'CONSOLIDADO DE CIERRE'!$A:$L,7,0) -> 59.593679 | E32: =IF(F32="","",E31+1) | L32: =IFERROR(__xludf.DUMMYFUNCTION("""COMPUTED_VALUE"""),"INCAPACIDAD LARGAS") -> INCAPACIDAD LARGAS | M32: =IFERROR(__xludf.DUMMYFUNCTION("""COMPUTED_VALUE"""),0.0) -> 0 | O32: =IFERROR(__xludf.DUMMYFUNCTION("""COMPUTED_VALUE"""),0.0) -> 0
B33: =IFERROR(__xludf.DUMMYFUNCTION("""COMPUTED_VALUE"""),"RENDIMIENTO NETO (visceras/hora)") -> RENDIMIENTO NETO (visceras/hora) | C33: =VLOOKUP($B$3,'CONSOLIDADO DE CIERRE'!$A:$L,8,0) -> 67.175573 | E33: =IF(F33="","",E32+1) | M33: =IFERROR(__xludf.DUMMYFUNCTION("""COMPUTED_VALUE"""),51.0) -> 51 | O33: =IFERROR(__xludf.DUMMYFUNCTION("""COMPUTED_VALUE"""),52.0) -> 52
B34: =IFERROR(__xludf.DUMMYFUNCTION("""COMPUTED_VALUE"""),"RENDIMIENTO (visceras/hr/hombre)") -> RENDIMIENTO (visceras/hr/hombre) | C34: =VLOOKUP($B$3, 'CONSOLIDADO DE CIERRE'!$A:$L, 9, 0) -> 1.241535 | E34: =IF(F34="","",E33+1)
B35: =IFERROR(__xludf.DUMMYFUNCTION("""COMPUTED_VALUE"""),"MINUTOS PAROS PROGRAMADOS") -> MINUTOS PAROS PROGRAMADOS | C35: =VLOOKUP($B$3,'CONSOLIDADO DE CIERRE'!$A:$L,10,0) -> 30 | E35: =IF(F35="","",E34+1)
B36: =IFERROR(__xludf.DUMMYFUNCTION("""COMPUTED_VALUE"""),"MINUTOS PAROS NO PROGRAMADOS") -> MINUTOS PAROS NO PROGRAMADOS | C36: =VLOOKUP($B$3,'CONSOLIDADO DE CIERRE'!$A:$L,11,0) -> 20 | E36: =IF(F36="","",E35+1)
B37: =IFERROR(__xludf.DUMMYFUNCTION("""COMPUTED_VALUE"""),"NOVEDADES:") -> NOVEDADES: | C37: =VLOOKUP($B$3,'CONSOLIDADO DE CIERRE'!$A:$L,12,0) | E37: TOTAL | G37: =SUM(G27:G36) -> 52 | H37: =SUM(H27:H36) -> 1 | I37: TOTAL AUSENTISMO | J37: =H37-H27 -> 0.076923077
B40: DISTRIBUCION DE PERSONAL PLANTA DE BENEFICIO
B42: LINEA DE BENEFICIO | F42: PCCOM | I42: =B3 -> 46261
B43: CARGO | F43: CARGO | I43: =CONCATENATE("Hora de Inicio proceso: *",TEXT("00:00",C6),"*") -> Hora de Inicio proceso: *15:10*
B44: ENMANGADO | C44: 1 | F44: IMPRESIÓN DE BRAZALETES | H44: 1 | I44: =CONCATENATE("Hora fin proceso: *",TEXT("00:00",C7),"*") -> Hora fin proceso: *21:53*
...

Sheet BASE DE DATOS CIERRE
A1: FECHA | B1: INDICADOE O.E.E | C1: TOTAL DE BENEFICIO | D1: HORA DE INICIO | E1: HORA FIN | F1: Duracion minutos | G1: TIEMPO DE PARADAS (min) | H1: PARADA PROGRAMADA (min) | I1: VELOCIDAD LÍNEA DE BENEFICIO | J1: HORAS LABORADAS | K1: TARDANZA DE INICIO | L1: PRODUCTIVIDAD | M1: VELOCIDAD NETA | N1: VELOCIDAD BRUTA | O1: TOLERANCIA CERO | P1: PIELES | Q1: CORTE EN PIERNA | R1: SOBREBARRIGAS ROTAS | S1: COBERTURA GRASA | T1: HEMATOMAS | U1: TOTAL PIELES ROTAS | V1: OBSERVACION | W1: % tiempo improductivo | X1: Capacidad Instalada | Y1: Liberación canales | Z1: Disponibilidad | AA1: Rendimiento | AB1: Calidad | AC1: MES | AD1: AÑO
A2: 46094 | B2: {=IF(Z2:Z1000="","",Z2:Z1000*AA2:AA1000*AB2:AB1000)} -> 0 | C2: 421 | D2: 0.58333333 | E2: 0.88125 | F2: {=IF(E2:E1000="","",(E2:E1000-D2:D1000)*24*60)} -> 429 | G2: 61 | H2: 30 | I2: {=M2:M1000} -> 74.733728 | J2: {=IF(F2:F1000="","",(F2:F1000/60))} -> 7.15 | K2: 0 | L2: {=IFERROR($C$2:$C1000/(($F$2:F1000-$H$2:H1000)/60),"")} -> 63.308271 | M2: {=IFERROR(C2:C1000/((F2:F1000-(H2:H1000+G2:G1000))/60),"")} -> 74.733728 | N2: {=IFERROR(C2:C1000/J2:J1000,"")} -> 58.881119 | O2: 0.0096 | P2: {=IFERROR((U2:U1000/C2:C1000),"")} -> 0.023752969 | Q2: {=IFERROR(VLOOKUP($A2:$A50,'LIBERACION DE CANALES'!$B50:$K1000,9,0),"")} | R2: {=IFERROR(VLOOKUP($A2:$A50,'LIBERACION DE CANALES'!$B50:$K1000,10,0),"")} | S2: {=IFERROR(VLOOKUP($A2:$A50,'LIBERACION DE CANALES'!$B50:$K1000,7,0),"")} | T2: {=IFERROR(VLOOKUP($A2:$A50,'LIBERACION DE CANALES'!$B50:$K1000,8,0),"")} | U2: 10 | W2: {=IF(G2:G1000="","",G2:G1000/F2:F1000)} -> 0.14219114 | X2: {=IF(M2:M1000>75,M2:M1000,75)} -> 75 | Y2: {=IF(Q2:Q1000="","",Q2:Q1000+R2:R1000+S2:S1000+T2:T1000)} | Z2: {=IF(W2:W1000="","",1-W2:W1000)} -> 0.85780886 | AA2: {=IF(W2:W1000="","",M2:M1000/X2:X1000)} -> 0.9964497 | AB2: {=IF(Y2:Y1000="","",1-Y2:Y1000)} | AC2: {=UPPER(TEXT($A$2:$A1000,"MMMM"))} -> MARZO | AD2: {=UPPER(TEXT($A$2:$A1000,"YYY"))} -> 2026
A3: =IF(C3="","",A2+1) -> 46095 | B3: 0 | C3: 231 | D3: 0.625 | E3: 0.76597222 | F3: 203 | G3: 9 | H3: 30 | I3: 84.512195 | J3: 3.3833333 | K3: 0 | L3: 80.115607 | M3: 84.512195 | N3: 68.275862 | O3: 0.0033 | P3: 0.017316017 | U3: 4 | W3: 0.044334975 | X3: 84.512195 | Z3: 0.95566502 | AA3: 1 | AC3: MARZO | AD3: 2026
A4: =IF(C4="","",A3+1) -> 46096 | C4: 0 | AC4: MARZO | AD4: 2026
A5: =IF(C5="","",A4+1) -> 46097 | B5: 0 | C5: 554 | D5: 0.58333333 | E5: 0.91805556 | F5: 482 | G5: 30 | H5: 30 | I5: 78.767773 | J5: 8.0333333 | K5: 0 | L5: 73.539823 | M5: 78.767773 | N5: 68.962656 | O5: 0.0027 | P5: 0.02166065 | U5: 12 | W5: 0.062240664 | X5: 78.767773 | Z5: 0.93775934 | AA5: 1 | AC5: MARZO | AD5: 2026
A6: =IF(C6="","",A5+1) -> 46098 | B6: 0 | C6: 501 | D6: 0.58333333 | E6: 0.89166667 | F6: 444 | G6: 17 | H6: 30 | I6: 75.717884 | J6: 7.4 | K6: 0 | L6: 72.608696 | M6: 75.717884 | N6: 67.702703 | O6: 0.0096 | P6: 0.031936128 | U6: 16 | W6: 0.038288288 | X6: 75.717884 | Z6: 0.96171171 | AA6: 1 | AC6: MARZO | AD6: 2026
A7: =IF(C7="","",A6+1) -> 46099 | B7: 0 | C7: 322 | D7: 0.625 | E7: 0.85 | F7: 324 | G7: 30 | H7: 30 | I7: 73.181818 | J7: 5.4 | K7: 0 | L7: 65.714286 | M7: 73.181818 | N7: 59.62963 | O7: 0.0024 | P7: 0.01863354 | U7: 6 | W7: 0.092592593 | X7: 75 | Z7: 0.90740741 | AA7: 0.97575758 | AC7: MARZO | AD7: 2026
A8: =IF(C8="","",A7+1) -> 46100 | B8: 0 | C8: 618 | D8: 0.58333333 | E8: 0.95763889 | F8: 539 | G8: 37 | H8: 45 | I8: 81.137856 | J8: 8.9833333 | K8: 0 | L8: 75.060729 | M8: 81.137856 | N8: 68.794063 | O8: 0.0157 | P8: 0.021035599 | U8: 13 | W8: 0.06864564 | X8: 81.137856 | Z8: 0.93135436 | AA8: 1 | AC8: MARZO | AD8: 2026
A9: =IF(C9="","",A8+1) -> 46101 | B9: 0 | C9: 398 | D9: 0.58333333 | E9: 0.82916667 | F9: 354 | G9: 0 | H9: 30.4 | I9: 73.794808 | J9: 5.9 | K9: 0 | L9: 73.794808 | M9: 73.794808 | N9: 67.457627 | O9: 0.0032 | P9: 0.015075377 | U9: 6 | W9: 0 | X9: 75 | Z9: 1 | AA9: 0.98393078 | AC9: MARZO | AD9: 2026
A10: =IF(C10="","",A9+1) -> 46102 | B10: 0 | C10: 313 | D10: 0.625 | E10: 0.78055556 | F10: 224 | G10: 6 | H10: 0 | I10: 86.146789 | J10: 3.7333333 | K10: 0 | L10: 83.839286 | M10: 86.146789 | N10: 83.839286 | O10: 0.0048 | P10: 0.028753994 | U10: 9 | W10: 0.026785714 | X10: 86.146789 | Z10: 0.97321429 | AA10: 1 | AC10: MARZO | AD10: 2026
A11: =IF(C11="","",A10+1) -> 46103 | C11: 0 | AC11: MARZO | AD11: 2026
A12: =IF(C12="","",A11+1) -> 46104 | B12: 0 | C12: 721 | D12: 0.58333333 | E12: 1.0652778 | F12: 694 | G12: 30 | H12: 60 | I12: 71.622517 | J12: 11.566667 | K12: 0 | L12: 68.233438 | M12: 71.622517 | N12: 62.334294 | O12: 0.001 | P12: 0.012482663 | U12: 9 | W12: 0.043227666 | X12: 75 | Z12: 0.95677233 | AA12: 0.95496689 | AC12: MARZO | AD12: 2026
A13: =IF(C13="","",A12+1) -> 46105 | B13: 0 | C13: 328 | D13: 0.625 | E13: 0.82986111 | F13: 295 | G13: 20 | H13: 0 | I13: 71.563636 | J13: 4.9166667 | K13: 0 | L13: 66.711864 | M13: 71.563636 | N13: 66.711864 | O13: 0.0076 | P13: 0.018292683 | U13: 6 | V13: 1. Se registra parada debido a cambio de manguera de cuchillos neumáticos (8). 2. Se registra parada por animal atascado en el box de noqueó (6). 3. Se registra parada por cambio de cuchillas de cuchillos neumáticos (6). 4. Disnimucion de velocidad debido a alto porcentaje de ausentismo (Se requiroi mover personal reubiado para poder cubrir puestos de trabajo). | W13: 0.06779661 | X13: 75 | Z13: 0.93220339 | AA13: 0.95418182 | AC13: MARZO | AD13: 2026
A14: =IF(C14="","",A13+1) -> 46106 | B14: 0 | C14: 359 | D14: 0.625 | E14: 0.85902778 | F14: 337 | G14: 15 | H14: 30 | I14: 73.767123 | J14: 5.6166667 | K14: 0 | L14: 70.162866 | M14: 73.767123 | N14: 63.916914 | O14: 0.0049 | P14: 0.030640669 | U14: 11 | V14: 1. Se presenta parada por baja presión en cuchillos neumáticos y box (8). 2. Se registra parada por acumulacion en puesto de trabajo desolladora (4) (esto es debido a que se tuvo que poner personal en entrenamiento para darle descanso a titulares. 3.Se registra parada debido a sin animales, para continuar el proceso (3). | W14: 0.044510386 | X14: 75 | Z14: 0.95548961 | AA14: 0.98356164 | AC14: MARZO | AD14: 2026
A15: =IF(C15="","",A14+1) -> 46107 | B15: 0 | C15: 504 | D15: 0.58333333 | E15: 0.89305556 | F15: 446 | G15: 35 | H15: 30 | I15: 79.370079 | J15: 7.4333333 | K15: 0 | L15: 72.692308 | M15: 79.370079 | N15: 67.802691 | O15: 0.007 | P15: 0.035714286 | U15: 18 | W15: 0.078475336 | X15: 79.370079 | Z15: 0.92152466 | AA15: 1 | AC15: MARZO | AD15: 2026
A16: =IF(C16="","",A15+1) -> 46108 | B16: 0 | C16: 337 | D16: 0.625 | E16: 0.82708333 | F16: 291 | G16: 0 | H16: 30 | I16: 77.471264 | J16: 4.85 | K16: 0 | L16: 77.471264 | M16: 77.471264 | N16: 69.484536 | O16: 0.0067 | P16: 0.03264095 | U16: 11 | V16: 1. Se realiza parada porgramada para dar tiempo a animales por tiempos de ayudo | W16: 0 | X16: 77.471264 | Z16: 1 | AA16: 1 | AC16: MARZO | AD16: 2026
A17: =IF(C17="","",A16+1) -> 46109 | B17: 0 | C17: 456 | D17: 0.62986111 | E17: 0.90138889 | F17: 391 | G17: 36 | H17: 30 | I17: 84.184615 | J17: 6.5166667 | K17: 7 | L17: 75.789474 | M17: 84.184615 | N17: 69.974425 | O17: 0.0071 | P17: 0 | V17: 1. Se registra parada debido acumulación de canales en zona Intermedia debido a la novedad de sirt (6). 2. Se registra parada debido a gualla que se sale de polea en desensor de guilletes (3). 3. Se registra parada debido a gualla que se sale de freno manual de corte de manos (14). 4. Se registra parada para ajustar cadera de desolladora (13). | W17: 0.092071611 | X17: 84.184615 | Z17: 0.90792839 | AA17: 1 | AC17: MARZO | AD17: 2026
A18: =IF(C18="","",A17+1) -> 46110 | C18: 0 | AC18: MARZO | AD18: 2026
A19: =IF(C19="","",A18+1) -> 46111 | B19: 0 | C19: 678 | D19: 0.58333333 | E19: 1.0104167 | F19: 615 | G19: 20 | H19: 60 | I19: 76.037383 | J19: 10.25 | K19: 0 | L19: 73.297297 | M19: 76.037383 | N19: 66.146341 | O19: 0.0019 | P19: 0.028023599 | U19: 19 | V19: 1. Se registra parada debido a novedad con plataforma de eviscerado de blanca (15). 2. Se registra parada debido animal que se desprende el tendón (5). | W19: 0.032520325 | X19: 76.037383 | Z19: 0.96747967 | AA19: 1 | AC19: MARZO | AD19: 2026
A20: =IF(C20="","",A19+1) -> 46112 | B20: 0 | C20: 430 | D20: 0.58333333 | E20: 0.85138889 | F20: 386 | G20: =5+9 -> 14 | H20: 30 | I20: 75.438596 | J20: 6.4333333 | K20: 0 | L20: 72.47191 | M20: 75.438596 | N20: 66.839378 | O20: 0.0029 | P20: 0.023255814 | U20: 10 | V20: 1. Se registra parada por animal atascado en el riel de Izado, no encarra correctamente en el riel debido al péndulo que se genera al subir (9). 2. Se registra parada debido a techo de manga de ingreso a box que se cae (5). | W20: 0.03626943 | X20: 75.438596 | Z20: 0.96373057 | AA20: 1 | AC20: MARZO | AD20: 2026
A21: =IF(C21="","",A20+1) -> 46113 | B21: 0 | C21: 316 | D21: 0.58333333 | E21: 1.1701389 | F21: 845 | G21: 590 | H21: 0 | I21: 74.352941 | J21: 14.083333 | K21: 0 | L21: 22.43787 | M21: 74.352941 | N21: 22.43787 | O21: 0.0032 | P21: 0.018987342 | U21: 6 | V21: 1. Se registra parada debido a que no se cuenta con fluido eléctrico en planta benéficio (590 min de tiempo improductivo). | W21: 0.69822485 | X21: 75 | Z21: 0.30177515 | AA21: 0.99137255 | AC21: ABRIL | AD21: 2026
A22: =IF(C22="","",A21+1) -> 46114 | C22: 0 | AC22: ABRIL | AD22: 2026
A23: =IF(C23="","",A22+1) -> 46115 | C23: 0 | AC23: ABRIL | AD23: 2026
A24: =IF(C24="","",A23+1) -> 46116 | B24: 0 | C24: 431 | D24: 0.625 | E24: 0.87777778 | F24: 364 | G24: 0 | H24: 30 | I24: 77.42515 | J24: 6.0666667 | K24: 0 | L24: 77.42515 | M24: 77.42515 | N24: 71.043956 | O24: 0.007 | P24: 0.027842227 | U24: 12 | W24: 0 | X24: 77.42515 | Z24: 1 | AA24: 1 | AC24: ABRIL | AD24: 2026
A25: =IF(C25="","",A24+1) -> 46117 | C25: 0 | K25: 0 | AC25: ABRIL | AD25: 2026
A26: =IF(C26="","",A25+1) -> 46118 | B26: 0 | C26: 679 | D26: 0.58333333 | E26: 1.0368056 | F26: 653 | G26: 77 | H26: 60 | I26: 78.953488 | J26: 10.883333 | K26: 0 | L26: 68.701518 | M26: 78.953488 | N26: 62.388974 | O26: 0.008 | P26: 0.025036819 | U26: 17 | V26: 1. Se registra parada por válvula del temporizador cerrada (7min) 2. se registra parada por falla en el final de carrera de la plataforma titular de la desolladora (18min) 3. se registra parada por acumulación de canales en el puesto de corte de esternón, debido a falla en las dos sierras ( titular con perdida de fuerza y contingencia con pulsador directo) (20min) 4. se registra parada por tanque cañón de pieles tapado debido al beneficio de 50 Búfalos de Olímpica (24min) 5.se registra parada por animal atascado de una pata, en la manga de ingreso al box (8min) | W26: 0.1179173 | X26: 78.953488 | Z26: 0.8820827 | AA26: 1 | AC26: ABRIL | AD26: 2026
A27: =IF(C27="","",A26+1) -> 46119 | B27: 0 | C27: 445 | D27: 0.58333333 | E27: 0.89305556 | F27: 446 | G27: 30 | H27: 35 | I27: 70.07874 | J27: 7.4333333 | K27: 0 | L27: 64.963504 | M27: 70.07874 | N27: 59.865471 | O27: 0.0084 | P27: 0.024719101 | U27: 11 | V27: 1. Se presenta parada por novedad en transferencia 1 (9) 2. Se registra parada por animal atascado en el riel de Izado, no encarra correctamente en el riel debido al péndulo que se genera al subir. (9). 3. - Se registra parada debido a guilletes que se queda atascado en freno manual de escornado (12). 4. Se evidencia una desminucion de velocidad debido al alto porcentaje de ausentismo y cansancio de personal. | W27: 0.067264574 | X27: 75 | Z27: 0.93273543 | AA27: 0.9343832 | AC27: ABRIL | AD27: 2026
A28: =IF(C28="","",A27+1) -> 46120 | B28: 0 | C28: 489 | D28: 0.58333333 | E28: 0.91666667 | F28: 480 | G28: 70 | H28: 30 | I28: 77.210526 | J28: 8 | K28: 0 | L28: 65.2 | M28: 77.210526 | N28: 61.125 | O28: 0.0118 | P28: 0 | V28: 1. Se registra parada por falla en el final de carrera de la plataforma titular de la desolladora (21) 2. Se registra parada por cable suelto de pedal subir plataforma titular de desoresdora (20). 3. - Se registra parada debido a cable suelto en control de box. (6). 4. Se registra parada debido animal que no ingresa a box por tener los cachos grandes y se queda atascado en mango de ingreso (9). 5. Se registra parada por animal que no queria ingresar a box y tábano no estaba funcionando (10). 6. Se registra parada debido a animal caído en manga ingreso a box (4). | W28: 0.14583333 | X28: 77.210526 | Z28: 0.85416667 | AA28: 1 | AC28: ABRIL | AD28: 2026
A29: =IF(C29="","",A28+1) -> 46121 | B29: 0 | C29: 564 | D29: 0.58333333 | E29: 0.92291667 | F29: 489 | G29: 23 | H29: 30 | I29: 77.614679 | J29: 8.15 | K29: 0 | L29: 73.72549 | M29: 77.614679 | N29: 69.202454 | O29: 0.0081 | P29: 0.023049645 | U29: 13 | V29: 1. Se presenta parada por el descensor de guilletes que se queda pegado a mitad y se demora en atender, ya que técnico estába atendiendo otra solicitud (5) 2. Se registra parada sin animales en manga ingreso al box (2) 3. Se registra parada debido a básculas con memoria llena, (técnico no tenía conocimiento como hacer el procedimiento de borrado)(16) 4. Se presenta accidente grave al operario Barajas fidel, estando en puesto emmangado se sube en box y compeñero al momento de cerrar puertas de ingreso a box le apriciona el dedo indice de mano izquierda. | W29: 0.047034765 | X29: 77.614679 | Z29: 0.95296524 | AA29: 1 | AC29: ABRIL | AD29: 2026
A30: =IF(C30="","",A29+1) -> 46122 | B30: 0 | C30: 240 | D30: 0.625 | E30: 0.79166667 | F30: 240 | G30: 6 | H30: 35 | I30: 72.361809 | J30: 4 | K30: 0 | L30: 70.243902 | M30: 72.361809 | N30: 60 | O30: 0.0031 | P30: 0.029166667 | U30: 7 | V30: 1. Se registra parada por fallo en frenos automáticos de linea ( electro válvula pegada) (6) 2. Se realiza parada programada para dar tiempo a reses que no cumplian tiempos de ayuno, por ser bajo el beneficio no podimos cumplir con velocidad | W30: 0.025 | X30: 75 | Z30: 0.975 | AA30: 0.96482412 | AC30: ABRIL | AD30: 2026
A31: =IF(C31="","",A30+1) -> 46123 | B31: 0 | C31: 233 | D31: 0.625 | E31: 0.7625 | F31: 198 | G31: 14 | H31: 0 | I31: 75.978261 | J31: 3.3 | K31: 0 | L31: 70.606061 | M31: 75.978261 | N31: 70.606061 | O31: 0.0043 | P31: 0.034334764 | U31: 8 | V31: 1. Se registra parada por acumulaciónde de reses en desolladora debido a novedad con personal (8) 2. Se registra parada por cambio de cuchillas de cuchillo izquierdo (6) | W31: 0.070707071 | X31: 75.978261 | Z31: 0.92929293 | AA31: 1 | AC31: ABRIL | AD31: 2026
A32: =IF(C32="","",A31+1) -> 46124 | C32: 0 | AC32: ABRIL | AD32: 2026
A33: =IF(C33="","",A32+1) -> 46125 | B33: 0 | C33: 627 | D33: 0.58333333 | E33: 1.0208333 | F33: 630 | G33: 70 | H33: 60 | I33: 75.24 | J33: 10.5 | K33: 0 | L33: 66 | M33: 75.24 | N33: 59.714286 | O33: 0.0048 | P33: 0.022328549 | U33: 14 | V33: 1. Se registra parada debido a ajuste de personal (8) 2. e registra parada debido a novedad por fuga de amoniaco (44). 3.Se registra parada por novedad de impresora de identificación de canales (18) | W33: 0.11111111 | X33: 75.24 | Z33: 0.88888889 | AA33: 1 | AC33: ABRIL | AD33: 2026
A34: =IF(C34="","",A33+1) -> 46126 | B34: 0 | C34: 289 | D34: 0.58333333 | E34: 0.7875 | F34: 294 | G34: 29 | H34: 30 | I34: 73.787234 | J34: 4.9 | K34: 0 | L34: 65.681818 | M34: 73.787234 | N34: 58.979592 | O34: 0.0069 | P34: 0.038062284 | U34: 11 | V34: 1. Se registra parada sin animales en mangal (13) 2. Se registra parada por revisión y lubricacion de cuchillos neumáticos (6) 3.Se registra parada por falta de ganado en manga por novedad en bañadera (4) 4.Se registra parada por animal atascado en riel debido al péndulo que genera al subir (6). 5. Se evidencia indicador alto en cobertura grasa y piele rotas, novedad relacionada a cuchillos derecho, la cual se tuvo detener proceso para revisar y lubricar /en cuanto a velocidad tambien impacto la intermitencia de ingreso de ganado al box. | W34: 0.098639456 | X34: 75 | Z34: 0.90136054 | AA34: 0.98382979 | AC34: ABRIL | AD34: 2026
A35: =IF(C35="","",A34+1) -> 46127 | B35: 0 | C35: 483 | D35: 0.625 | E35: 0.91458333 | F35: 417 | G35: 46 | H35: 30 | I35: 84.985337 | J35: 6.95 | K35: 0 | L35: 74.883721 | M35: 84.985337 | N35: 69.496403 | O35: 0.0202 | P35: 0.01863354 | U35: 9 | V35: 1. Se registra parada sin animales en manga de ingreso a box (17) 2.Se registra parada para despejar acumulación de canales en fin de linea (5). 3. Se registra parada por lamina suelta de compuerta de descarga box (10). 4. Se registra parada por acumulación de canales en sierra canal debido a cambio de cinta (5) 5. Se registra parada por apartado, liberación y lavado de reses adicionales (9) 6. Se presentan desviaciones de proceso relacionada a los puestos anudado de esogafos y corte de esternon, debido a poca rotacion por el alto % de ausentismo | W35: 0.11031175 | X35: 84.985337 | Z35: 0.88968825 | AA35: 1 | AC35: ABRIL | AD35: 2026
A36: =IF(C36="","",A35+1) -> 46128 | B36: 0 | C36: 688 | D36: 0.58333333 | E36: 1.0583333 | F36: 684 | G36: 99 | H36: 65 | I36: 79.384615 | J36: 11.4 | K36: 0 | L36: 66.688207 | M36: 79.384615 | N36: 60.350877 | O36: 0.007 | P36: 0.018895349 | U36: 13 | V36: 1. Se registra parada debido a novedad con los dos tábanos que dejaron de funcionar y los animales no ingresaban a manga ingreso box (25) 2.Se registra parada debido a acumulación de canales por recambio de brazalestes por novedad de impresora (26). 3.Se registra parada por animal caído en manga ingreso a box (10) 4.Se registra parada por animal atascado en el riel de Izado, no encarra correctamente en el riel debido al péndulo que se genera al subir. (4) 5.Se registra parada por ajuste de personal. (3) 6.Se registra parada por acumulación de canales debido a la verificación de canales de cliente Olímpica con reporte de hallazgos (13) 7.Se registra parada por res caída en manga (10) 8.Se registra parada por res acalambrada en manga de ingreso corrales (8) | W36: 0.14473684 | X36: 79.384615 | Z36: 0.85526316 | AA36: 1 | AC36: ABRIL | AD36: 2026
A37: =IF(C37="","",A36+1) -> 46129 | B37: 0 | C37: 573 | D37: 0.58333333 | E37: 0.95763889 | F37: 539 | G37: 54 | H37: 30 | I37: 75.56044 | J37: 8.9833333 | K37: 0 | L37: 67.544204 | M37: 75.56044 | N37: 63.784787 | O37: 0.0039 | P37: 0.012216405 | U37: 7 | V37: 1. Se registra parada debido a guaya de freno manual de desolladora se sale de polea (6) 2.Se registra parada por el cambio de guaya en mal estaso de freno Manual de desolladora (8). 3. Se registra parada sin animales en la manga debido a corrales no tenía información de reses planilladas adicionales (10). 4.Se registra parada por 12 animales adicionales que no fueron apartados en corrales (30) | W37: 0.10018553 | X37: 75.56044 | Z37: 0.89981447 | AA37: 1 | AC37: ABRIL | AD37: 2026
A38: =IF(C38="","",A37+1) -> 46130 | B38: 0 | C38: 292 | D38: 0.625 | E38: 0.79861111 | F38: 250 | G38: =15+4+4 -> 23 | H38: 0 | I38: 77.180617 | J38: 4.1666667 | K38: 0 | L38: 70.08 | M38: 77.180617 | N38: 70.08 | O38: 0.0052 | P38: 0.017123288 | U38: 5 | V38: 1. Se registra parada por animal caído en manga (4) 2.Se registra parada debido animales volteados en manga ingreso corrales (4). 3. Se registra parada debido a revision y cambio de contactos de control de transferencia #1 (15). 4. Se evidencia impacto en indicador de corte en piernas asociado a la poca rotacion del personal por el alto % de ausentismo. | W38: 0.092 | X38: 77.180617 | Z38: 0.908 | AA38: 1 | AC38: ABRIL | AD38: 2026
A39: =IF(C39="","",A38+1) -> 46131 | C39: 0 | AC39: ABRIL | AD39: 2026
A40: =IF(C40="","",A39+1) -> 46132 | B40: 0 | C40: 610 | D40: 0.625 | E40: 1.0388889 | F40: 596 | G40: 84 | H40: 60 | I40: 80.973451 | J40: 9.9333333 | K40: 0 | L40: 68.283582 | M40: 80.973451 | N40: 61.409396 | O40: 0.0095 | P40: 0.013114754 | U40: 8 | V40: 1. Se registra parada debido a rompimiento de una de las manguera de tijeras neumática # 2 (27) 2.Se registra parada por acumulación de canales en zona limpia debido a paso de cliente institucional (5). 3. Se registra parada debido animal enredado en cadena de compuerta de manga ingreso corrale (37). 4.Se registra parada debido a gualla de freno manual de eviscerado de blanca que se sale de perro. (5) 5.Se registra parada debido a soldadura de compuerta de apretamiento de box (5) 6.Se registra parada debido a cilindro de box que se suelta (5) | W40: 0.1409396 | X40: 80.973451 | Z40: 0.8590604 | AA40: 1 | AC40: ABRIL | AD40: 2026
...

Sheet CONSOLIDADO DE CIERRE
A1: FECHA | B1: TOTAL DE BENEFICO | C1: HORA INICIO CABEZAS | D1: HORA ULTIMA VISCERA AMARRADA | E1: TOTAL PAROS | F1: DURACIÓN PROCESO (Hrs) | G1: RENDIMIENTO BRUTO (visceras/hora) | H1: RENDIMIENTO NETO (visceras/hora) | I1: RENDIMIENTO (visceras/hr/hombre) | J1: MINUTOS PAROS PROGRAMADOS | K1: MINUTOS PAROS NO PROGRAMADOS | L1: NOVEDADES: | M1: =IFERROR(__xludf.DUMMYFUNCTION("TRANSPOSE(IMPORTRANGE(""https://docs.google.com/spreadsheets/d/1CNeKSHTeNNJnfn5EymHwGg5Mkuk6EcepW7_9QkJxalc/edit#gid=1218471306"",""ENERO 2024!E2:AJ21""))"),"PERSONAL ASIGNADO") -> PERSONAL ASIGNADO | N1: =IFERROR(__xludf.DUMMYFUNCTION("""COMPUTED_VALUE"""),"PERSONAL CONTRATADO") -> PERSONAL CONTRATADO | O1: =IFERROR(__xludf.DUMMYFUNCTION("""COMPUTED_VALUE"""),"COMPENSATORIO") -> COMPENSATORIO | P1: =IFERROR(__xludf.DUMMYFUNCTION("""COMPUTED_VALUE"""),"PERMISO") -> PERMISO | Q1: =IFERROR(__xludf.DUMMYFUNCTION("""COMPUTED_VALUE"""),"AUSENTISMO") -> AUSENTISMO | R1: =IFERROR(__xludf.DUMMYFUNCTION("""COMPUTED_VALUE"""),"RENUNCIA") -> RENUNCIA | S1: =IFERROR(__xludf.DUMMYFUNCTION("""COMPUTED_VALUE"""),"INCAPACIDAD") -> INCAPACIDAD | T1: =IFERROR(__xludf.DUMMYFUNCTION("""COMPUTED_VALUE"""),"CALAMIDAD") -> CALAMIDAD | U1: =IFERROR(__xludf.DUMMYFUNCTION("""COMPUTED_VALUE"""),"PDTE POR CONTRATAR") -> PDTE POR CONTRATAR | V1: =IFERROR(__xludf.DUMMYFUNCTION("""COMPUTED_VALUE"""),"VACACIONES") -> VACACIONES | W1: =IFERROR(__xludf.DUMMYFUNCTION("""COMPUTED_VALUE"""),"SUSPENSION") -> SUSPENSION | X1: =IFERROR(__xludf.DUMMYFUNCTION("""COMPUTED_VALUE"""),"REUBICADO") -> REUBICADO | Y1: =IFERROR(__xludf.DUMMYFUNCTION("""COMPUTED_VALUE"""),"LICENCIA") -> LICENCIA | Z1: =IFERROR(__xludf.DUMMYFUNCTION("""COMPUTED_VALUE"""),"AMORTIZAR EXTRAS") -> AMORTIZAR EXTRAS | AA1: =IFERROR(__xludf.DUMMYFUNCTION("""COMPUTED_VALUE"""),"DIA DE CERO ACCIDENTE") -> DIA DE CERO ACCIDENTE | AB1: =IFERROR(__xludf.DUMMYFUNCTION("""COMPUTED_VALUE"""),"INDUCCION") -> INDUCCION | AC1: =IFERROR(__xludf.DUMMYFUNCTION("""COMPUTED_VALUE"""),"DIA DE LA FAMILIA") -> DIA DE LA FAMILIA | AD1: =IFERROR(__xludf.DUMMYFUNCTION("""COMPUTED_VALUE"""),"PERSONAL PRESENTE") -> PERSONAL PRESENTE | AE1: =IFERROR(__xludf.DUMMYFUNCTION("""COMPUTED_VALUE"""),"PERSONAL AUSENTE") -> PERSONAL AUSENTE | AF1: =IFERROR(__xludf.DUMMYFUNCTION("""COMPUTED_VALUE"""),"PENDIENTES POR CONTRATAR") -> PENDIENTES POR CONTRATAR | AG1: MES | AH1: AÑO | AI1: SEBO | AJ1: CYC
A2: 45292 | B2: 0 | E2: {=IF(B2=0,"",(J2+K2)/60)} | F2: =IF(B2=0,"",HOUR(D2-C2)+(MINUTE(D2-C2)/60)) | G2: =IF(B2=0,"",B2/F2) | H2: =IF(B2=0,"",B2/(F2-E2)) | I2: =IF(B2=0,"",B2/F2/AD2) | M2: =IFERROR(__xludf.DUMMYFUNCTION("""COMPUTED_VALUE"""),57.0) -> 57 | N2: =IFERROR(__xludf.DUMMYFUNCTION("""COMPUTED_VALUE"""),49.0) -> 49 | O2: =IFERROR(__xludf.DUMMYFUNCTION("""COMPUTED_VALUE"""),0.0) -> 0 | P2: =IFERROR(__xludf.DUMMYFUNCTION("""COMPUTED_VALUE"""),0.0) -> 0 | Q2: =IFERROR(__xludf.DUMMYFUNCTION("""COMPUTED_VALUE"""),0.0) -> 0 | R2: =IFERROR(__xludf.DUMMYFUNCTION("""COMPUTED_VALUE"""),0.0) -> 0 | S2: =IFERROR(__xludf.DUMMYFUNCTION("""COMPUTED_VALUE"""),0.0) -> 0 | T2: =IFERROR(__xludf.DUMMYFUNCTION("""COMPUTED_VALUE"""),0.0) -> 0 | U2: =IFERROR(__xludf.DUMMYFUNCTION("""COMPUTED_VALUE"""),6.0) -> 6 | V2: =IFERROR(__xludf.DUMMYFUNCTION("""COMPUTED_VALUE"""),0.0) -> 0 | W2: =IFERROR(__xludf.DUMMYFUNCTION("""COMPUTED_VALUE"""),0.0) -> 0 | X2: =IFERROR(__xludf.DUMMYFUNCTION("""COMPUTED_VALUE"""),0.0) -> 0 | Y2: =IFERROR(__xludf.DUMMYFUNCTION("""COMPUTED_VALUE"""),0.0) -> 0 | Z2: =IFERROR(__xludf.DUMMYFUNCTION("""COMPUTED_VALUE"""),0.0) -> 0 | AA2: =IFERROR(__xludf.DUMMYFUNCTION("""COMPUTED_VALUE"""),0.0) -> 0 | AB2: =IFERROR(__xludf.DUMMYFUNCTION("""COMPUTED_VALUE"""),0.0) -> 0 | AC2: =IFERROR(__xludf.DUMMYFUNCTION("""COMPUTED_VALUE"""),0.0) -> 0 | AD2: =IFERROR(__xludf.DUMMYFUNCTION("""COMPUTED_VALUE"""),0.0) -> 0 | AE2: =IFERROR(__xludf.DUMMYFUNCTION("""COMPUTED_VALUE"""),8.0) -> 8 | AF2: =IFERROR(__xludf.DUMMYFUNCTION("""COMPUTED_VALUE"""),8.0) -> 8 | AG2: {=UPPER(TEXT(A2:A1366,"MMMM"))} -> ENERO | AH2: {=UPPER(TEXT(A2:A1366,"YYY"))} -> 2024
A3: =IF(B3="","",A2+1) -> 45293 | B3: 309 | C3: 0.51597222 | D3: 0.75694444 | E3: {=IF(B3=0,"",(J3+K3)/60)} -> 0.25 | F3: =IF(B3=0,"",HOUR(D3-C3)+(MINUTE(D3-C3)/60)) -> 5.7833333 | G3: =IF(B3=0,"",B3/F3) -> 53.429395 | H3: =IF(B3=0,"",B3/(F3-E3)) -> 55.843373 | I3: =IF(B3=0,"",B3/F3/AD3) -> 1.3699845 | J3: 15 | M3: =IFERROR(__xludf.DUMMYFUNCTION("""COMPUTED_VALUE"""),57.0) -> 57 | N3: =IFERROR(__xludf.DUMMYFUNCTION("""COMPUTED_VALUE"""),49.0) -> 49 | O3: =IFERROR(__xludf.DUMMYFUNCTION("""COMPUTED_VALUE"""),0.0) -> 0 | P3: =IFERROR(__xludf.DUMMYFUNCTION("""COMPUTED_VALUE"""),0.0) -> 0 | Q3: =IFERROR(__xludf.DUMMYFUNCTION("""COMPUTED_VALUE"""),3.0) -> 3 | R3: =IFERROR(__xludf.DUMMYFUNCTION("""COMPUTED_VALUE"""),0.0) -> 0 | S3: =IFERROR(__xludf.DUMMYFUNCTION("""COMPUTED_VALUE"""),3.0) -> 3 | T3: =IFERROR(__xludf.DUMMYFUNCTION("""COMPUTED_VALUE"""),0.0) -> 0 | U3: =IFERROR(__xludf.DUMMYFUNCTION("""COMPUTED_VALUE"""),6.0) -> 6 | V3: =IFERROR(__xludf.DUMMYFUNCTION("""COMPUTED_VALUE"""),4.0) -> 4 | W3: =IFERROR(__xludf.DUMMYFUNCTION("""COMPUTED_VALUE"""),0.0) -> 0 | X3: =IFERROR(__xludf.DUMMYFUNCTION("""COMPUTED_VALUE"""),0.0) -> 0 | Y3: =IFERROR(__xludf.DUMMYFUNCTION("""COMPUTED_VALUE"""),0.0) -> 0 | Z3: =IFERROR(__xludf.DUMMYFUNCTION("""COMPUTED_VALUE"""),2.0) -> 2 | AA3: =IFERROR(__xludf.DUMMYFUNCTION("""COMPUTED_VALUE"""),0.0) -> 0 | AB3: =IFERROR(__xludf.DUMMYFUNCTION("""COMPUTED_VALUE"""),0.0) -> 0 | AC3: =IFERROR(__xludf.DUMMYFUNCTION("""COMPUTED_VALUE"""),0.0) -> 0 | AD3: =IFERROR(__xludf.DUMMYFUNCTION("""COMPUTED_VALUE"""),39.0) -> 39 | AE3: =IFERROR(__xludf.DUMMYFUNCTION("""COMPUTED_VALUE"""),20.0) -> 20 | AF3: =IFERROR(__xludf.DUMMYFUNCTION("""COMPUTED_VALUE"""),8.0) -> 8 | AG3: ENERO | AH3: 2024
A4: =IF(B4="","",A3+1) -> 45294 | B4: 595 | C4: 0.55833333 | D4: 1.0208333 | E4: {=IF(B4=0,"",(J4+K4)/60)} -> 1.1 | F4: =IF(B4=0,"",HOUR(D4-C4)+(MINUTE(D4-C4)/60)) -> 11.1 | G4: =IF(B4=0,"",B4/F4) -> 53.603604 | H4: =IF(B4=0,"",B4/(F4-E4)) -> 59.5 | I4: =IF(B4=0,"",B4/F4/AD4) -> 1.2762763 | J4: 60 | K4: 6 | M4: =IFERROR(__xludf.DUMMYFUNCTION("""COMPUTED_VALUE"""),57.0) -> 57 | N4: =IFERROR(__xludf.DUMMYFUNCTION("""COMPUTED_VALUE"""),48.0) -> 48 | O4: =IFERROR(__xludf.DUMMYFUNCTION("""COMPUTED_VALUE"""),0.0) -> 0 | P4: =IFERROR(__xludf.DUMMYFUNCTION("""COMPUTED_VALUE"""),0.0) -> 0 | Q4: =IFERROR(__xludf.DUMMYFUNCTION("""COMPUTED_VALUE"""),0.0) -> 0 | R4: =IFERROR(__xludf.DUMMYFUNCTION("""COMPUTED_VALUE"""),0.0) -> 0 | S4: =IFERROR(__xludf.DUMMYFUNCTION("""COMPUTED_VALUE"""),4.0) -> 4 | T4: =IFERROR(__xludf.DUMMYFUNCTION("""COMPUTED_VALUE"""),0.0) -> 0 | U4: =IFERROR(__xludf.DUMMYFUNCTION("""COMPUTED_VALUE"""),7.0) -> 7 | V4: =IFERROR(__xludf.DUMMYFUNCTION("""COMPUTED_VALUE"""),4.0) -> 4 | W4: =IFERROR(__xludf.DUMMYFUNCTION("""COMPUTED_VALUE"""),0.0) -> 0 | X4: =IFERROR(__xludf.DUMMYFUNCTION("""COMPUTED_VALUE"""),0.0) -> 0 | Y4: =IFERROR(__xludf.DUMMYFUNCTION("""COMPUTED_VALUE"""),0.0) -> 0 | Z4: =IFERROR(__xludf.DUMMYFUNCTION("""COMPUTED_VALUE"""),0.0) -> 0 | AA4: =IFERROR(__xludf.DUMMYFUNCTION("""COMPUTED_VALUE"""),0.0) -> 0 | AB4: =IFERROR(__xludf.DUMMYFUNCTION("""COMPUTED_VALUE"""),0.0) -> 0 | AC4: =IFERROR(__xludf.DUMMYFUNCTION("""COMPUTED_VALUE"""),0.0) -> 0 | AD4: =IFERROR(__xludf.DUMMYFUNCTION("""COMPUTED_VALUE"""),42.0) -> 42 | AE4: =IFERROR(__xludf.DUMMYFUNCTION("""COMPUTED_VALUE"""),17.0) -> 17 | AF4: =IFERROR(__xludf.DUMMYFUNCTION("""COMPUTED_VALUE"""),9.0) -> 9 | AG4: ENERO | AH4: 2024
A5: =IF(B5="","",A4+1) -> 45295 | B5: 538 | C5: 0.51666667 | D5: 0.92222222 | E5: {=IF(B5=0,"",(J5+K5)/60)} -> 1.25 | F5: =IF(B5=0,"",HOUR(D5-C5)+(MINUTE(D5-C5)/60)) -> 9.7333333 | G5: =IF(B5=0,"",B5/F5) -> 55.273973 | H5: =IF(B5=0,"",B5/(F5-E5)) -> 63.418468 | I5: =IF(B5=0,"",B5/F5/AD5) -> 1.2283105 | J5: 15 | K5: 60 | M5: =IFERROR(__xludf.DUMMYFUNCTION("""COMPUTED_VALUE"""),57.0) -> 57 | N5: =IFERROR(__xludf.DUMMYFUNCTION("""COMPUTED_VALUE"""),49.0) -> 49 | O5: =IFERROR(__xludf.DUMMYFUNCTION("""COMPUTED_VALUE"""),0.0) -> 0 | P5: =IFERROR(__xludf.DUMMYFUNCTION("""COMPUTED_VALUE"""),0.0) -> 0 | Q5: =IFERROR(__xludf.DUMMYFUNCTION("""COMPUTED_VALUE"""),0.0) -> 0 | R5: =IFERROR(__xludf.DUMMYFUNCTION("""COMPUTED_VALUE"""),0.0) -> 0 | S5: =IFERROR(__xludf.DUMMYFUNCTION("""COMPUTED_VALUE"""),2.0) -> 2 | T5: =IFERROR(__xludf.DUMMYFUNCTION("""COMPUTED_VALUE"""),0.0) -> 0 | U5: =IFERROR(__xludf.DUMMYFUNCTION("""COMPUTED_VALUE"""),6.0) -> 6 | V5: =IFERROR(__xludf.DUMMYFUNCTION("""COMPUTED_VALUE"""),4.0) -> 4 | W5: =IFERROR(__xludf.DUMMYFUNCTION("""COMPUTED_VALUE"""),0.0) -> 0 | X5: =IFERROR(__xludf.DUMMYFUNCTION("""COMPUTED_VALUE"""),0.0) -> 0 | Y5: =IFERROR(__xludf.DUMMYFUNCTION("""COMPUTED_VALUE"""),0.0) -> 0 | Z5: =IFERROR(__xludf.DUMMYFUNCTION("""COMPUTED_VALUE"""),0.0) -> 0 | AA5: =IFERROR(__xludf.DUMMYFUNCTION("""COMPUTED_VALUE"""),0.0) -> 0 | AB5: =IFERROR(__xludf.DUMMYFUNCTION("""COMPUTED_VALUE"""),0.0) -> 0 | AC5: =IFERROR(__xludf.DUMMYFUNCTION("""COMPUTED_VALUE"""),0.0) -> 0 | AD5: =IFERROR(__xludf.DUMMYFUNCTION("""COMPUTED_VALUE"""),45.0) -> 45 | AE5: =IFERROR(__xludf.DUMMYFUNCTION("""COMPUTED_VALUE"""),14.0) -> 14 | AF5: =IFERROR(__xludf.DUMMYFUNCTION("""COMPUTED_VALUE"""),8.0) -> 8 | AG5: ENERO | AH5: 2024
